[2025-04-05T15:12:13.456+0000] {local_task_job_runner.py:123} INFO - ::group::Pre task execution logs
[2025-04-05T15:12:13.470+0000] {taskinstance.py:2614} INFO - Dependencies all met for dep_context=non-requeueable deps ti=<TaskInstance: adhan_etl_weekly.fetch_and_insert_cities scheduled__2025-03-23T00:00:00+00:00 [queued]>
[2025-04-05T15:12:13.476+0000] {taskinstance.py:2614} INFO - Dependencies all met for dep_context=requeueable deps ti=<TaskInstance: adhan_etl_weekly.fetch_and_insert_cities scheduled__2025-03-23T00:00:00+00:00 [queued]>
[2025-04-05T15:12:13.478+0000] {taskinstance.py:2867} INFO - Starting attempt 1 of 2
[2025-04-05T15:12:13.620+0000] {taskinstance.py:2890} INFO - Executing <Task(PythonOperator): fetch_and_insert_cities> on 2025-03-23 00:00:00+00:00
[2025-04-05T15:12:13.627+0000] {warnings.py:112} WARNING - /home/***/.local/lib/python3.12/site-packages/***/task/task_runner/standard_task_runner.py:70: DeprecationWarning: This process (pid=76) is multi-threaded, use of fork() may lead to deadlocks in the child.
  pid = os.fork()

[2025-04-05T15:12:13.629+0000] {standard_task_runner.py:72} INFO - Started process 78 to run task
[2025-04-05T15:12:13.628+0000] {standard_task_runner.py:104} INFO - Running: ['***', 'tasks', 'run', 'adhan_etl_weekly', 'fetch_and_insert_cities', 'scheduled__2025-03-23T00:00:00+00:00', '--job-id', '805', '--raw', '--subdir', 'DAGS_FOLDER/PrayerTimePipeline.py', '--cfg-path', '/tmp/tmpi6ynmr6k']
[2025-04-05T15:12:13.630+0000] {standard_task_runner.py:105} INFO - Job 805: Subtask fetch_and_insert_cities
[2025-04-05T15:12:13.679+0000] {task_command.py:467} INFO - Running <TaskInstance: adhan_etl_weekly.fetch_and_insert_cities scheduled__2025-03-23T00:00:00+00:00 [running]> on host a31a66c6b7c5
[2025-04-05T15:12:13.761+0000] {taskinstance.py:3134} INFO - Exporting env vars: AIRFLOW_CTX_DAG_OWNER='***' AIRFLOW_CTX_DAG_ID='adhan_etl_weekly' AIRFLOW_CTX_TASK_ID='fetch_and_insert_cities' AIRFLOW_CTX_EXECUTION_DATE='2025-03-23T00:00:00+00:00' AIRFLOW_CTX_TRY_NUMBER='1' AIRFLOW_CTX_DAG_RUN_ID='scheduled__2025-03-23T00:00:00+00:00'
[2025-04-05T15:12:13.763+0000] {logging_mixin.py:190} INFO - Task instance is in running state
[2025-04-05T15:12:13.764+0000] {logging_mixin.py:190} INFO -  Previous state of the Task instance: queued
[2025-04-05T15:12:13.764+0000] {logging_mixin.py:190} INFO - Current task name:fetch_and_insert_cities state:running start_date:2025-04-05 15:12:13.471265+00:00
[2025-04-05T15:12:13.765+0000] {logging_mixin.py:190} INFO - Dag name:adhan_etl_weekly and current dag run status:running
[2025-04-05T15:12:13.765+0000] {taskinstance.py:732} INFO - ::endgroup::
[2025-04-05T15:12:13.766+0000] {taskinstance.py:3313} ERROR - Task failed with exception
Traceback (most recent call last):
  File "/home/airflow/.local/lib/python3.12/site-packages/airflow/models/taskinstance.py", line 768, in _execute_task
    result = _execute_callable(context=context, **execute_callable_kwargs)
             ^^^^^^^^^^^^^^^^^^^^^^^^^^^^^^^^^^^^^^^^^^^^^^^^^^^^^^^^^^^^^
  File "/home/airflow/.local/lib/python3.12/site-packages/airflow/models/taskinstance.py", line 734, in _execute_callable
    return ExecutionCallableRunner(
           ^^^^^^^^^^^^^^^^^^^^^^^^
  File "/home/airflow/.local/lib/python3.12/site-packages/airflow/utils/operator_helpers.py", line 252, in run
    return self.func(*args, **kwargs)
           ^^^^^^^^^^^^^^^^^^^^^^^^^^
  File "/home/airflow/.local/lib/python3.12/site-packages/airflow/models/baseoperator.py", line 424, in wrapper
    return func(self, *args, **kwargs)
           ^^^^^^^^^^^^^^^^^^^^^^^^^^^
  File "/home/airflow/.local/lib/python3.12/site-packages/airflow/operators/python.py", line 238, in execute
    return_value = self.execute_callable()
                   ^^^^^^^^^^^^^^^^^^^^^^^
  File "/home/airflow/.local/lib/python3.12/site-packages/airflow/operators/python.py", line 256, in execute_callable
    return runner.run(*self.op_args, **self.op_kwargs)
           ^^^^^^^^^^^^^^^^^^^^^^^^^^^^^^^^^^^^^^^^^^^
  File "/home/airflow/.local/lib/python3.12/site-packages/airflow/utils/operator_helpers.py", line 252, in run
    return self.func(*args, **kwargs)
           ^^^^^^^^^^^^^^^^^^^^^^^^^^
  File "/opt/airflow/dags/PrayerTimePipeline.py", line 27, in fetch_and_insert_cities
    conn, cur = get_conn_cursor()
                ^^^^^^^^^^^^^^^^^
  File "/opt/airflow/dags/PrayerTimePipeline.py", line 11, in get_conn_cursor
    conn = psycopg2.connect(
           ^^^^^^^^^^^^^^^^^
  File "/home/airflow/.local/lib/python3.12/site-packages/psycopg2/__init__.py", line 122, in connect
    conn = _connect(dsn, connection_factory=connection_factory, **kwasync)
           ^^^^^^^^^^^^^^^^^^^^^^^^^^^^^^^^^^^^^^^^^^^^^^^^^^^^^^^^^^^^^^^
psycopg2.OperationalError: connection to server at "localhost" (::1), port 5432 failed: Connection refused
	Is the server running on that host and accepting TCP/IP connections?
connection to server at "localhost" (127.0.0.1), port 5432 failed: Connection refused
	Is the server running on that host and accepting TCP/IP connections?

[2025-04-05T15:12:13.783+0000] {logging_mixin.py:190} INFO - Task instance in failure state
[2025-04-05T15:12:13.784+0000] {logging_mixin.py:190} INFO - Task start:2025-04-05 15:12:13.471265+00:00 end:2025-04-05 15:12:13.782724+00:00 duration:0.311459
[2025-04-05T15:12:13.784+0000] {logging_mixin.py:190} INFO - Task:<Task(PythonOperator): fetch_and_insert_cities> dag:<DAG: adhan_etl_weekly> dagrun:<DagRun adhan_etl_weekly @ 2025-03-23 00:00:00+00:00: scheduled__2025-03-23T00:00:00+00:00, state:running, queued_at: 2025-04-05 15:12:11.578037+00:00. externally triggered: False>
[2025-04-05T15:12:13.784+0000] {logging_mixin.py:190} INFO - Failure caused by connection to server at "localhost" (::1), port 5432 failed: Connection refused
	Is the server running on that host and accepting TCP/IP connections?
connection to server at "localhost" (127.0.0.1), port 5432 failed: Connection refused
	Is the server running on that host and accepting TCP/IP connections?
[2025-04-05T15:12:13.785+0000] {taskinstance.py:1226} INFO - Marking task as UP_FOR_RETRY. dag_id=adhan_etl_weekly, task_id=fetch_and_insert_cities, run_id=scheduled__2025-03-23T00:00:00+00:00, execution_date=20250323T000000, start_date=20250405T151213, end_date=20250405T151213
[2025-04-05T15:12:13.814+0000] {taskinstance.py:341} INFO - ::group::Post task execution logs
[2025-04-05T15:12:13.815+0000] {standard_task_runner.py:124} ERROR - Failed to execute job 805 for task fetch_and_insert_cities (connection to server at "localhost" (::1), port 5432 failed: Connection refused
	Is the server running on that host and accepting TCP/IP connections?
connection to server at "localhost" (127.0.0.1), port 5432 failed: Connection refused
	Is the server running on that host and accepting TCP/IP connections?
; 78)
Traceback (most recent call last):
  File "/home/airflow/.local/lib/python3.12/site-packages/airflow/task/task_runner/standard_task_runner.py", line 117, in _start_by_fork
    ret = args.func(args, dag=self.dag)
          ^^^^^^^^^^^^^^^^^^^^^^^^^^^^^
  File "/home/airflow/.local/lib/python3.12/site-packages/airflow/cli/cli_config.py", line 49, in command
    return func(*args, **kwargs)
           ^^^^^^^^^^^^^^^^^^^^^
  File "/home/airflow/.local/lib/python3.12/site-packages/airflow/utils/cli.py", line 116, in wrapper
    return f(*args, **kwargs)
           ^^^^^^^^^^^^^^^^^^
  File "/home/airflow/.local/lib/python3.12/site-packages/airflow/cli/commands/task_command.py", line 483, in task_run
    task_return_code = _run_task_by_selected_method(args, _dag, ti)
                       ^^^^^^^^^^^^^^^^^^^^^^^^^^^^^^^^^^^^^^^^^^^^
  File "/home/airflow/.local/lib/python3.12/site-packages/airflow/cli/commands/task_command.py", line 256, in _run_task_by_selected_method
    return _run_raw_task(args, ti)
           ^^^^^^^^^^^^^^^^^^^^^^^
  File "/home/airflow/.local/lib/python3.12/site-packages/airflow/cli/commands/task_command.py", line 341, in _run_raw_task
    return ti._run_raw_task(
           ^^^^^^^^^^^^^^^^^
  File "/home/airflow/.local/lib/python3.12/site-packages/airflow/utils/session.py", line 97, in wrapper
    return func(*args, session=session, **kwargs)
           ^^^^^^^^^^^^^^^^^^^^^^^^^^^^^^^^^^^^^^
  File "/home/airflow/.local/lib/python3.12/site-packages/airflow/models/taskinstance.py", line 3006, in _run_raw_task
    return _run_raw_task(
           ^^^^^^^^^^^^^^
  File "/home/airflow/.local/lib/python3.12/site-packages/airflow/models/taskinstance.py", line 274, in _run_raw_task
    TaskInstance._execute_task_with_callbacks(
  File "/home/airflow/.local/lib/python3.12/site-packages/airflow/models/taskinstance.py", line 3161, in _execute_task_with_callbacks
    result = self._execute_task(context, task_orig)
             ^^^^^^^^^^^^^^^^^^^^^^^^^^^^^^^^^^^^^^
  File "/home/airflow/.local/lib/python3.12/site-packages/airflow/models/taskinstance.py", line 3185, in _execute_task
    return _execute_task(self, context, task_orig)
           ^^^^^^^^^^^^^^^^^^^^^^^^^^^^^^^^^^^^^^^
  File "/home/airflow/.local/lib/python3.12/site-packages/airflow/models/taskinstance.py", line 768, in _execute_task
    result = _execute_callable(context=context, **execute_callable_kwargs)
             ^^^^^^^^^^^^^^^^^^^^^^^^^^^^^^^^^^^^^^^^^^^^^^^^^^^^^^^^^^^^^
  File "/home/airflow/.local/lib/python3.12/site-packages/airflow/models/taskinstance.py", line 734, in _execute_callable
    return ExecutionCallableRunner(
           ^^^^^^^^^^^^^^^^^^^^^^^^
  File "/home/airflow/.local/lib/python3.12/site-packages/airflow/utils/operator_helpers.py", line 252, in run
    return self.func(*args, **kwargs)
           ^^^^^^^^^^^^^^^^^^^^^^^^^^
  File "/home/airflow/.local/lib/python3.12/site-packages/airflow/models/baseoperator.py", line 424, in wrapper
    return func(self, *args, **kwargs)
           ^^^^^^^^^^^^^^^^^^^^^^^^^^^
  File "/home/airflow/.local/lib/python3.12/site-packages/airflow/operators/python.py", line 238, in execute
    return_value = self.execute_callable()
                   ^^^^^^^^^^^^^^^^^^^^^^^
  File "/home/airflow/.local/lib/python3.12/site-packages/airflow/operators/python.py", line 256, in execute_callable
    return runner.run(*self.op_args, **self.op_kwargs)
           ^^^^^^^^^^^^^^^^^^^^^^^^^^^^^^^^^^^^^^^^^^^
  File "/home/airflow/.local/lib/python3.12/site-packages/airflow/utils/operator_helpers.py", line 252, in run
    return self.func(*args, **kwargs)
           ^^^^^^^^^^^^^^^^^^^^^^^^^^
  File "/opt/airflow/dags/PrayerTimePipeline.py", line 27, in fetch_and_insert_cities
    conn, cur = get_conn_cursor()
                ^^^^^^^^^^^^^^^^^
  File "/opt/airflow/dags/PrayerTimePipeline.py", line 11, in get_conn_cursor
    conn = psycopg2.connect(
           ^^^^^^^^^^^^^^^^^
  File "/home/airflow/.local/lib/python3.12/site-packages/psycopg2/__init__.py", line 122, in connect
    conn = _connect(dsn, connection_factory=connection_factory, **kwasync)
           ^^^^^^^^^^^^^^^^^^^^^^^^^^^^^^^^^^^^^^^^^^^^^^^^^^^^^^^^^^^^^^^
psycopg2.OperationalError: connection to server at "localhost" (::1), port 5432 failed: Connection refused
	Is the server running on that host and accepting TCP/IP connections?
connection to server at "localhost" (127.0.0.1), port 5432 failed: Connection refused
	Is the server running on that host and accepting TCP/IP connections?

[2025-04-05T15:12:13.845+0000] {local_task_job_runner.py:266} INFO - Task exited with return code 1
[2025-04-05T15:12:13.872+0000] {taskinstance.py:3901} INFO - 0 downstream tasks scheduled from follow-on schedule check
[2025-04-05T15:12:13.874+0000] {local_task_job_runner.py:245} INFO - ::endgroup::
