[2025-04-05T15:38:28.786+0000] {local_task_job_runner.py:123} INFO - ::group::Pre task execution logs
[2025-04-05T15:38:28.802+0000] {taskinstance.py:2614} INFO - Dependencies all met for dep_context=non-requeueable deps ti=<TaskInstance: adhan_etl_weekly.fetch_and_insert_cities manual__2025-04-05T15:20:26.154008+00:00 [queued]>
[2025-04-05T15:38:28.810+0000] {taskinstance.py:2614} INFO - Dependencies all met for dep_context=requeueable deps ti=<TaskInstance: adhan_etl_weekly.fetch_and_insert_cities manual__2025-04-05T15:20:26.154008+00:00 [queued]>
[2025-04-05T15:38:28.811+0000] {taskinstance.py:2867} INFO - Starting attempt 2 of 2
[2025-04-05T15:38:28.999+0000] {taskinstance.py:2890} INFO - Executing <Task(PythonOperator): fetch_and_insert_cities> on 2025-04-05 15:20:26.154008+00:00
[2025-04-05T15:38:29.007+0000] {warnings.py:112} WARNING - /home/***/.local/lib/python3.12/site-packages/***/task/task_runner/standard_task_runner.py:70: DeprecationWarning: This process (pid=119) is multi-threaded, use of fork() may lead to deadlocks in the child.
  pid = os.fork()

[2025-04-05T15:38:29.009+0000] {standard_task_runner.py:72} INFO - Started process 124 to run task
[2025-04-05T15:38:29.009+0000] {standard_task_runner.py:104} INFO - Running: ['***', 'tasks', 'run', 'adhan_etl_weekly', 'fetch_and_insert_cities', 'manual__2025-04-05T15:20:26.154008+00:00', '--job-id', '815', '--raw', '--subdir', 'DAGS_FOLDER/PrayerTimePipeline.py', '--cfg-path', '/tmp/tmpfxhx5x_j']
[2025-04-05T15:38:29.010+0000] {standard_task_runner.py:105} INFO - Job 815: Subtask fetch_and_insert_cities
[2025-04-05T15:38:29.065+0000] {task_command.py:467} INFO - Running <TaskInstance: adhan_etl_weekly.fetch_and_insert_cities manual__2025-04-05T15:20:26.154008+00:00 [running]> on host 83fc34a9e46f
[2025-04-05T15:38:29.146+0000] {taskinstance.py:3134} INFO - Exporting env vars: AIRFLOW_CTX_DAG_OWNER='***' AIRFLOW_CTX_DAG_ID='adhan_etl_weekly' AIRFLOW_CTX_TASK_ID='fetch_and_insert_cities' AIRFLOW_CTX_EXECUTION_DATE='2025-04-05T15:20:26.154008+00:00' AIRFLOW_CTX_TRY_NUMBER='2' AIRFLOW_CTX_DAG_RUN_ID='manual__2025-04-05T15:20:26.154008+00:00'
[2025-04-05T15:38:29.147+0000] {logging_mixin.py:190} INFO - Task instance is in running state
[2025-04-05T15:38:29.148+0000] {logging_mixin.py:190} INFO -  Previous state of the Task instance: queued
[2025-04-05T15:38:29.149+0000] {logging_mixin.py:190} INFO - Current task name:fetch_and_insert_cities state:running start_date:2025-04-05 15:38:28.802933+00:00
[2025-04-05T15:38:29.149+0000] {logging_mixin.py:190} INFO - Dag name:adhan_etl_weekly and current dag run status:running
[2025-04-05T15:38:29.150+0000] {taskinstance.py:732} INFO - ::endgroup::
[2025-04-05T15:38:29.152+0000] {taskinstance.py:3313} ERROR - Task failed with exception
Traceback (most recent call last):
  File "/home/airflow/.local/lib/python3.12/site-packages/airflow/models/taskinstance.py", line 768, in _execute_task
    result = _execute_callable(context=context, **execute_callable_kwargs)
             ^^^^^^^^^^^^^^^^^^^^^^^^^^^^^^^^^^^^^^^^^^^^^^^^^^^^^^^^^^^^^
  File "/home/airflow/.local/lib/python3.12/site-packages/airflow/models/taskinstance.py", line 734, in _execute_callable
    return ExecutionCallableRunner(
           ^^^^^^^^^^^^^^^^^^^^^^^^
  File "/home/airflow/.local/lib/python3.12/site-packages/airflow/utils/operator_helpers.py", line 252, in run
    return self.func(*args, **kwargs)
           ^^^^^^^^^^^^^^^^^^^^^^^^^^
  File "/home/airflow/.local/lib/python3.12/site-packages/airflow/models/baseoperator.py", line 424, in wrapper
    return func(self, *args, **kwargs)
           ^^^^^^^^^^^^^^^^^^^^^^^^^^^
  File "/home/airflow/.local/lib/python3.12/site-packages/airflow/operators/python.py", line 238, in execute
    return_value = self.execute_callable()
                   ^^^^^^^^^^^^^^^^^^^^^^^
  File "/home/airflow/.local/lib/python3.12/site-packages/airflow/operators/python.py", line 256, in execute_callable
    return runner.run(*self.op_args, **self.op_kwargs)
           ^^^^^^^^^^^^^^^^^^^^^^^^^^^^^^^^^^^^^^^^^^^
  File "/home/airflow/.local/lib/python3.12/site-packages/airflow/utils/operator_helpers.py", line 252, in run
    return self.func(*args, **kwargs)
           ^^^^^^^^^^^^^^^^^^^^^^^^^^
  File "/opt/airflow/dags/PrayerTimePipeline.py", line 27, in fetch_and_insert_cities
    conn, cur = get_conn_cursor()
                ^^^^^^^^^^^^^^^^^
  File "/opt/airflow/dags/PrayerTimePipeline.py", line 11, in get_conn_cursor
    conn = psycopg2.connect(
           ^^^^^^^^^^^^^^^^^
  File "/home/airflow/.local/lib/python3.12/site-packages/psycopg2/__init__.py", line 122, in connect
    conn = _connect(dsn, connection_factory=connection_factory, **kwasync)
           ^^^^^^^^^^^^^^^^^^^^^^^^^^^^^^^^^^^^^^^^^^^^^^^^^^^^^^^^^^^^^^^
psycopg2.OperationalError: connection to server at "localhost" (::1), port 5432 failed: Connection refused
	Is the server running on that host and accepting TCP/IP connections?
connection to server at "localhost" (127.0.0.1), port 5432 failed: Connection refused
	Is the server running on that host and accepting TCP/IP connections?

[2025-04-05T15:38:29.164+0000] {logging_mixin.py:190} INFO - Task instance in failure state
[2025-04-05T15:38:29.165+0000] {logging_mixin.py:190} INFO - Task start:2025-04-05 15:38:28.802933+00:00 end:2025-04-05 15:38:29.163983+00:00 duration:0.36105
[2025-04-05T15:38:29.165+0000] {logging_mixin.py:190} INFO - Task:<Task(PythonOperator): fetch_and_insert_cities> dag:<DAG: adhan_etl_weekly> dagrun:<DagRun adhan_etl_weekly @ 2025-04-05 15:20:26.154008+00:00: manual__2025-04-05T15:20:26.154008+00:00, state:running, queued_at: 2025-04-05 15:20:26.166088+00:00. externally triggered: True>
[2025-04-05T15:38:29.166+0000] {logging_mixin.py:190} INFO - Failure caused by connection to server at "localhost" (::1), port 5432 failed: Connection refused
	Is the server running on that host and accepting TCP/IP connections?
connection to server at "localhost" (127.0.0.1), port 5432 failed: Connection refused
	Is the server running on that host and accepting TCP/IP connections?
[2025-04-05T15:38:29.166+0000] {taskinstance.py:1226} INFO - Marking task as FAILED. dag_id=adhan_etl_weekly, task_id=fetch_and_insert_cities, run_id=manual__2025-04-05T15:20:26.154008+00:00, execution_date=20250405T152026, start_date=20250405T153828, end_date=20250405T153829
[2025-04-05T15:38:29.193+0000] {taskinstance.py:341} INFO - ::group::Post task execution logs
[2025-04-05T15:38:29.194+0000] {standard_task_runner.py:124} ERROR - Failed to execute job 815 for task fetch_and_insert_cities (connection to server at "localhost" (::1), port 5432 failed: Connection refused
	Is the server running on that host and accepting TCP/IP connections?
connection to server at "localhost" (127.0.0.1), port 5432 failed: Connection refused
	Is the server running on that host and accepting TCP/IP connections?
; 124)
Traceback (most recent call last):
  File "/home/airflow/.local/lib/python3.12/site-packages/airflow/task/task_runner/standard_task_runner.py", line 117, in _start_by_fork
    ret = args.func(args, dag=self.dag)
          ^^^^^^^^^^^^^^^^^^^^^^^^^^^^^
  File "/home/airflow/.local/lib/python3.12/site-packages/airflow/cli/cli_config.py", line 49, in command
    return func(*args, **kwargs)
           ^^^^^^^^^^^^^^^^^^^^^
  File "/home/airflow/.local/lib/python3.12/site-packages/airflow/utils/cli.py", line 116, in wrapper
    return f(*args, **kwargs)
           ^^^^^^^^^^^^^^^^^^
  File "/home/airflow/.local/lib/python3.12/site-packages/airflow/cli/commands/task_command.py", line 483, in task_run
    task_return_code = _run_task_by_selected_method(args, _dag, ti)
                       ^^^^^^^^^^^^^^^^^^^^^^^^^^^^^^^^^^^^^^^^^^^^
  File "/home/airflow/.local/lib/python3.12/site-packages/airflow/cli/commands/task_command.py", line 256, in _run_task_by_selected_method
    return _run_raw_task(args, ti)
           ^^^^^^^^^^^^^^^^^^^^^^^
  File "/home/airflow/.local/lib/python3.12/site-packages/airflow/cli/commands/task_command.py", line 341, in _run_raw_task
    return ti._run_raw_task(
           ^^^^^^^^^^^^^^^^^
  File "/home/airflow/.local/lib/python3.12/site-packages/airflow/utils/session.py", line 97, in wrapper
    return func(*args, session=session, **kwargs)
           ^^^^^^^^^^^^^^^^^^^^^^^^^^^^^^^^^^^^^^
  File "/home/airflow/.local/lib/python3.12/site-packages/airflow/models/taskinstance.py", line 3006, in _run_raw_task
    return _run_raw_task(
           ^^^^^^^^^^^^^^
  File "/home/airflow/.local/lib/python3.12/site-packages/airflow/models/taskinstance.py", line 274, in _run_raw_task
    TaskInstance._execute_task_with_callbacks(
  File "/home/airflow/.local/lib/python3.12/site-packages/airflow/models/taskinstance.py", line 3161, in _execute_task_with_callbacks
    result = self._execute_task(context, task_orig)
             ^^^^^^^^^^^^^^^^^^^^^^^^^^^^^^^^^^^^^^
  File "/home/airflow/.local/lib/python3.12/site-packages/airflow/models/taskinstance.py", line 3185, in _execute_task
    return _execute_task(self, context, task_orig)
           ^^^^^^^^^^^^^^^^^^^^^^^^^^^^^^^^^^^^^^^
  File "/home/airflow/.local/lib/python3.12/site-packages/airflow/models/taskinstance.py", line 768, in _execute_task
    result = _execute_callable(context=context, **execute_callable_kwargs)
             ^^^^^^^^^^^^^^^^^^^^^^^^^^^^^^^^^^^^^^^^^^^^^^^^^^^^^^^^^^^^^
  File "/home/airflow/.local/lib/python3.12/site-packages/airflow/models/taskinstance.py", line 734, in _execute_callable
    return ExecutionCallableRunner(
           ^^^^^^^^^^^^^^^^^^^^^^^^
  File "/home/airflow/.local/lib/python3.12/site-packages/airflow/utils/operator_helpers.py", line 252, in run
    return self.func(*args, **kwargs)
           ^^^^^^^^^^^^^^^^^^^^^^^^^^
  File "/home/airflow/.local/lib/python3.12/site-packages/airflow/models/baseoperator.py", line 424, in wrapper
    return func(self, *args, **kwargs)
           ^^^^^^^^^^^^^^^^^^^^^^^^^^^
  File "/home/airflow/.local/lib/python3.12/site-packages/airflow/operators/python.py", line 238, in execute
    return_value = self.execute_callable()
                   ^^^^^^^^^^^^^^^^^^^^^^^
  File "/home/airflow/.local/lib/python3.12/site-packages/airflow/operators/python.py", line 256, in execute_callable
    return runner.run(*self.op_args, **self.op_kwargs)
           ^^^^^^^^^^^^^^^^^^^^^^^^^^^^^^^^^^^^^^^^^^^
  File "/home/airflow/.local/lib/python3.12/site-packages/airflow/utils/operator_helpers.py", line 252, in run
    return self.func(*args, **kwargs)
           ^^^^^^^^^^^^^^^^^^^^^^^^^^
  File "/opt/airflow/dags/PrayerTimePipeline.py", line 27, in fetch_and_insert_cities
    conn, cur = get_conn_cursor()
                ^^^^^^^^^^^^^^^^^
  File "/opt/airflow/dags/PrayerTimePipeline.py", line 11, in get_conn_cursor
    conn = psycopg2.connect(
           ^^^^^^^^^^^^^^^^^
  File "/home/airflow/.local/lib/python3.12/site-packages/psycopg2/__init__.py", line 122, in connect
    conn = _connect(dsn, connection_factory=connection_factory, **kwasync)
           ^^^^^^^^^^^^^^^^^^^^^^^^^^^^^^^^^^^^^^^^^^^^^^^^^^^^^^^^^^^^^^^
psycopg2.OperationalError: connection to server at "localhost" (::1), port 5432 failed: Connection refused
	Is the server running on that host and accepting TCP/IP connections?
connection to server at "localhost" (127.0.0.1), port 5432 failed: Connection refused
	Is the server running on that host and accepting TCP/IP connections?

[2025-04-05T15:38:29.226+0000] {local_task_job_runner.py:266} INFO - Task exited with return code 1
[2025-04-05T15:38:29.250+0000] {taskinstance.py:3901} INFO - 0 downstream tasks scheduled from follow-on schedule check
[2025-04-05T15:38:29.255+0000] {local_task_job_runner.py:245} INFO - ::endgroup::
