[2025-04-05T15:17:19.568+0000] {local_task_job_runner.py:123} INFO - ::group::Pre task execution logs
[2025-04-05T15:17:19.584+0000] {taskinstance.py:2614} INFO - Dependencies all met for dep_context=non-requeueable deps ti=<TaskInstance: adhan_insert_today_details.insert_current_day_details scheduled__2025-04-04T00:00:00+00:00 [queued]>
[2025-04-05T15:17:19.591+0000] {taskinstance.py:2614} INFO - Dependencies all met for dep_context=requeueable deps ti=<TaskInstance: adhan_insert_today_details.insert_current_day_details scheduled__2025-04-04T00:00:00+00:00 [queued]>
[2025-04-05T15:17:19.592+0000] {taskinstance.py:2867} INFO - Starting attempt 2 of 2
[2025-04-05T15:17:19.744+0000] {taskinstance.py:2890} INFO - Executing <Task(PythonOperator): insert_current_day_details> on 2025-04-04 00:00:00+00:00
[2025-04-05T15:17:19.752+0000] {warnings.py:112} WARNING - /home/***/.local/lib/python3.12/site-packages/***/task/task_runner/standard_task_runner.py:70: DeprecationWarning: This process (pid=156) is multi-threaded, use of fork() may lead to deadlocks in the child.
  pid = os.fork()

[2025-04-05T15:17:19.754+0000] {standard_task_runner.py:72} INFO - Started process 165 to run task
[2025-04-05T15:17:19.753+0000] {standard_task_runner.py:104} INFO - Running: ['***', 'tasks', 'run', 'adhan_insert_today_details', 'insert_current_day_details', 'scheduled__2025-04-04T00:00:00+00:00', '--job-id', '809', '--raw', '--subdir', 'DAGS_FOLDER/PrayerTimePipeline.py', '--cfg-path', '/tmp/tmpjypi83df']
[2025-04-05T15:17:19.755+0000] {standard_task_runner.py:105} INFO - Job 809: Subtask insert_current_day_details
[2025-04-05T15:17:19.813+0000] {task_command.py:467} INFO - Running <TaskInstance: adhan_insert_today_details.insert_current_day_details scheduled__2025-04-04T00:00:00+00:00 [running]> on host a31a66c6b7c5
[2025-04-05T15:17:19.894+0000] {taskinstance.py:3134} INFO - Exporting env vars: AIRFLOW_CTX_DAG_OWNER='***' AIRFLOW_CTX_DAG_ID='adhan_insert_today_details' AIRFLOW_CTX_TASK_ID='insert_current_day_details' AIRFLOW_CTX_EXECUTION_DATE='2025-04-04T00:00:00+00:00' AIRFLOW_CTX_TRY_NUMBER='2' AIRFLOW_CTX_DAG_RUN_ID='scheduled__2025-04-04T00:00:00+00:00'
[2025-04-05T15:17:19.896+0000] {logging_mixin.py:190} INFO - Task instance is in running state
[2025-04-05T15:17:19.897+0000] {logging_mixin.py:190} INFO -  Previous state of the Task instance: queued
[2025-04-05T15:17:19.898+0000] {logging_mixin.py:190} INFO - Current task name:insert_current_day_details state:running start_date:2025-04-05 15:17:19.585683+00:00
[2025-04-05T15:17:19.898+0000] {logging_mixin.py:190} INFO - Dag name:adhan_insert_today_details and current dag run status:running
[2025-04-05T15:17:19.899+0000] {taskinstance.py:732} INFO - ::endgroup::
[2025-04-05T15:17:19.900+0000] {taskinstance.py:3313} ERROR - Task failed with exception
Traceback (most recent call last):
  File "/home/airflow/.local/lib/python3.12/site-packages/airflow/models/taskinstance.py", line 768, in _execute_task
    result = _execute_callable(context=context, **execute_callable_kwargs)
             ^^^^^^^^^^^^^^^^^^^^^^^^^^^^^^^^^^^^^^^^^^^^^^^^^^^^^^^^^^^^^
  File "/home/airflow/.local/lib/python3.12/site-packages/airflow/models/taskinstance.py", line 734, in _execute_callable
    return ExecutionCallableRunner(
           ^^^^^^^^^^^^^^^^^^^^^^^^
  File "/home/airflow/.local/lib/python3.12/site-packages/airflow/utils/operator_helpers.py", line 252, in run
    return self.func(*args, **kwargs)
           ^^^^^^^^^^^^^^^^^^^^^^^^^^
  File "/home/airflow/.local/lib/python3.12/site-packages/airflow/models/baseoperator.py", line 424, in wrapper
    return func(self, *args, **kwargs)
           ^^^^^^^^^^^^^^^^^^^^^^^^^^^
  File "/home/airflow/.local/lib/python3.12/site-packages/airflow/operators/python.py", line 238, in execute
    return_value = self.execute_callable()
                   ^^^^^^^^^^^^^^^^^^^^^^^
  File "/home/airflow/.local/lib/python3.12/site-packages/airflow/operators/python.py", line 256, in execute_callable
    return runner.run(*self.op_args, **self.op_kwargs)
           ^^^^^^^^^^^^^^^^^^^^^^^^^^^^^^^^^^^^^^^^^^^
  File "/home/airflow/.local/lib/python3.12/site-packages/airflow/utils/operator_helpers.py", line 252, in run
    return self.func(*args, **kwargs)
           ^^^^^^^^^^^^^^^^^^^^^^^^^^
  File "/opt/airflow/dags/PrayerTimePipeline.py", line 99, in insert_current_day_details
    conn, cur = get_conn_cursor()
                ^^^^^^^^^^^^^^^^^
  File "/opt/airflow/dags/PrayerTimePipeline.py", line 11, in get_conn_cursor
    conn = psycopg2.connect(
           ^^^^^^^^^^^^^^^^^
  File "/home/airflow/.local/lib/python3.12/site-packages/psycopg2/__init__.py", line 122, in connect
    conn = _connect(dsn, connection_factory=connection_factory, **kwasync)
           ^^^^^^^^^^^^^^^^^^^^^^^^^^^^^^^^^^^^^^^^^^^^^^^^^^^^^^^^^^^^^^^
psycopg2.OperationalError: connection to server at "localhost" (::1), port 5432 failed: Connection refused
	Is the server running on that host and accepting TCP/IP connections?
connection to server at "localhost" (127.0.0.1), port 5432 failed: Connection refused
	Is the server running on that host and accepting TCP/IP connections?

[2025-04-05T15:17:19.916+0000] {logging_mixin.py:190} INFO - Task instance in failure state
[2025-04-05T15:17:19.916+0000] {logging_mixin.py:190} INFO - Task start:2025-04-05 15:17:19.585683+00:00 end:2025-04-05 15:17:19.915625+00:00 duration:0.329942
[2025-04-05T15:17:19.917+0000] {logging_mixin.py:190} INFO - Task:<Task(PythonOperator): insert_current_day_details> dag:<DAG: adhan_insert_today_details> dagrun:<DagRun adhan_insert_today_details @ 2025-04-04 00:00:00+00:00: scheduled__2025-04-04T00:00:00+00:00, state:running, queued_at: 2025-04-05 15:12:15.985608+00:00. externally triggered: False>
[2025-04-05T15:17:19.918+0000] {logging_mixin.py:190} INFO - Failure caused by connection to server at "localhost" (::1), port 5432 failed: Connection refused
	Is the server running on that host and accepting TCP/IP connections?
connection to server at "localhost" (127.0.0.1), port 5432 failed: Connection refused
	Is the server running on that host and accepting TCP/IP connections?
[2025-04-05T15:17:19.918+0000] {taskinstance.py:1226} INFO - Marking task as FAILED. dag_id=adhan_insert_today_details, task_id=insert_current_day_details, run_id=scheduled__2025-04-04T00:00:00+00:00, execution_date=20250404T000000, start_date=20250405T151719, end_date=20250405T151719
[2025-04-05T15:17:19.944+0000] {taskinstance.py:341} INFO - ::group::Post task execution logs
[2025-04-05T15:17:19.945+0000] {standard_task_runner.py:124} ERROR - Failed to execute job 809 for task insert_current_day_details (connection to server at "localhost" (::1), port 5432 failed: Connection refused
	Is the server running on that host and accepting TCP/IP connections?
connection to server at "localhost" (127.0.0.1), port 5432 failed: Connection refused
	Is the server running on that host and accepting TCP/IP connections?
; 165)
Traceback (most recent call last):
  File "/home/airflow/.local/lib/python3.12/site-packages/airflow/task/task_runner/standard_task_runner.py", line 117, in _start_by_fork
    ret = args.func(args, dag=self.dag)
          ^^^^^^^^^^^^^^^^^^^^^^^^^^^^^
  File "/home/airflow/.local/lib/python3.12/site-packages/airflow/cli/cli_config.py", line 49, in command
    return func(*args, **kwargs)
           ^^^^^^^^^^^^^^^^^^^^^
  File "/home/airflow/.local/lib/python3.12/site-packages/airflow/utils/cli.py", line 116, in wrapper
    return f(*args, **kwargs)
           ^^^^^^^^^^^^^^^^^^
  File "/home/airflow/.local/lib/python3.12/site-packages/airflow/cli/commands/task_command.py", line 483, in task_run
    task_return_code = _run_task_by_selected_method(args, _dag, ti)
                       ^^^^^^^^^^^^^^^^^^^^^^^^^^^^^^^^^^^^^^^^^^^^
  File "/home/airflow/.local/lib/python3.12/site-packages/airflow/cli/commands/task_command.py", line 256, in _run_task_by_selected_method
    return _run_raw_task(args, ti)
           ^^^^^^^^^^^^^^^^^^^^^^^
  File "/home/airflow/.local/lib/python3.12/site-packages/airflow/cli/commands/task_command.py", line 341, in _run_raw_task
    return ti._run_raw_task(
           ^^^^^^^^^^^^^^^^^
  File "/home/airflow/.local/lib/python3.12/site-packages/airflow/utils/session.py", line 97, in wrapper
    return func(*args, session=session, **kwargs)
           ^^^^^^^^^^^^^^^^^^^^^^^^^^^^^^^^^^^^^^
  File "/home/airflow/.local/lib/python3.12/site-packages/airflow/models/taskinstance.py", line 3006, in _run_raw_task
    return _run_raw_task(
           ^^^^^^^^^^^^^^
  File "/home/airflow/.local/lib/python3.12/site-packages/airflow/models/taskinstance.py", line 274, in _run_raw_task
    TaskInstance._execute_task_with_callbacks(
  File "/home/airflow/.local/lib/python3.12/site-packages/airflow/models/taskinstance.py", line 3161, in _execute_task_with_callbacks
    result = self._execute_task(context, task_orig)
             ^^^^^^^^^^^^^^^^^^^^^^^^^^^^^^^^^^^^^^
  File "/home/airflow/.local/lib/python3.12/site-packages/airflow/models/taskinstance.py", line 3185, in _execute_task
    return _execute_task(self, context, task_orig)
           ^^^^^^^^^^^^^^^^^^^^^^^^^^^^^^^^^^^^^^^
  File "/home/airflow/.local/lib/python3.12/site-packages/airflow/models/taskinstance.py", line 768, in _execute_task
    result = _execute_callable(context=context, **execute_callable_kwargs)
             ^^^^^^^^^^^^^^^^^^^^^^^^^^^^^^^^^^^^^^^^^^^^^^^^^^^^^^^^^^^^^
  File "/home/airflow/.local/lib/python3.12/site-packages/airflow/models/taskinstance.py", line 734, in _execute_callable
    return ExecutionCallableRunner(
           ^^^^^^^^^^^^^^^^^^^^^^^^
  File "/home/airflow/.local/lib/python3.12/site-packages/airflow/utils/operator_helpers.py", line 252, in run
    return self.func(*args, **kwargs)
           ^^^^^^^^^^^^^^^^^^^^^^^^^^
  File "/home/airflow/.local/lib/python3.12/site-packages/airflow/models/baseoperator.py", line 424, in wrapper
    return func(self, *args, **kwargs)
           ^^^^^^^^^^^^^^^^^^^^^^^^^^^
  File "/home/airflow/.local/lib/python3.12/site-packages/airflow/operators/python.py", line 238, in execute
    return_value = self.execute_callable()
                   ^^^^^^^^^^^^^^^^^^^^^^^
  File "/home/airflow/.local/lib/python3.12/site-packages/airflow/operators/python.py", line 256, in execute_callable
    return runner.run(*self.op_args, **self.op_kwargs)
           ^^^^^^^^^^^^^^^^^^^^^^^^^^^^^^^^^^^^^^^^^^^
  File "/home/airflow/.local/lib/python3.12/site-packages/airflow/utils/operator_helpers.py", line 252, in run
    return self.func(*args, **kwargs)
           ^^^^^^^^^^^^^^^^^^^^^^^^^^
  File "/opt/airflow/dags/PrayerTimePipeline.py", line 99, in insert_current_day_details
    conn, cur = get_conn_cursor()
                ^^^^^^^^^^^^^^^^^
  File "/opt/airflow/dags/PrayerTimePipeline.py", line 11, in get_conn_cursor
    conn = psycopg2.connect(
           ^^^^^^^^^^^^^^^^^
  File "/home/airflow/.local/lib/python3.12/site-packages/psycopg2/__init__.py", line 122, in connect
    conn = _connect(dsn, connection_factory=connection_factory, **kwasync)
           ^^^^^^^^^^^^^^^^^^^^^^^^^^^^^^^^^^^^^^^^^^^^^^^^^^^^^^^^^^^^^^^
psycopg2.OperationalError: connection to server at "localhost" (::1), port 5432 failed: Connection refused
	Is the server running on that host and accepting TCP/IP connections?
connection to server at "localhost" (127.0.0.1), port 5432 failed: Connection refused
	Is the server running on that host and accepting TCP/IP connections?

[2025-04-05T15:17:19.970+0000] {local_task_job_runner.py:266} INFO - Task exited with return code 1
[2025-04-05T15:17:19.987+0000] {taskinstance.py:3901} INFO - 0 downstream tasks scheduled from follow-on schedule check
[2025-04-05T15:17:19.990+0000] {local_task_job_runner.py:245} INFO - ::endgroup::
